<robot name="test_robot">
  <link name="world"/>

  <material name="red">
    <color rgba="1.0 0.0 0.0 1.0"/>
  </material>

  <joint name="world_2_base" type="floating">
    <parent link="world"/>
    <child link="base_link"/>
  </joint>
  <link name="base_link">
    <visual>
      <geometry>
        <box size="0.5 0.5 0.2"/>
      </geometry>
      <origin xyz="0 0 0" rpy="0 0 0"/>
      <material name="red"/>
    </visual>
  </link>

  <joint name="base_2_gnss" type="fixed">
    <parent link="base_link"/>
    <child link="gnss_link"/>
    <origin xyz="0 0 0.5"/>
  </joint>
  <link name="gnss_link">
    <visual>
      <geometry>
        <box size="0.1 0.1 0.1"/>
      </geometry>
      <origin xyz="0 0 0" rpy="0 0 0"/>
      <material name="red">
        <color rgba="1.0 0.0 0.0"/>
      </material>
    </visual>
  </link>
</robot>
